<mujoco>
  <compiler meshdir="./meshes"/>

  <asset>
    <material name="grid_floor" texture="grid" texrepeat="1 1" texuniform="true" reflectance=".2"/>
    <material name="gray" rgba="0.7 0.7 0.7 1"/>
    <mesh name="buddy_mushr_base_nano" file="mushr_base_nano.stl"/>
    <mesh name="buddy_mushr_wheel" file="mushr_wheel.stl"/>
    <texture name="grid" type="2d" builtin="checker" rgb1=".1 .2 .3"  rgb2=".2 .3 .4" width="300" height="300"/>
    <material name="grid" texture="grid" texrepeat="8 8" reflectance=".2"/>
  </asset>

  <default>
    <default class="buddy_wheel">
      <geom fitscale="1.2" type="ellipsoid" friction="2 0.005 0.0001" contype="1" conaffinity="1" mesh="buddy_mushr_wheel" mass="0.498952" rgba="0 0 0 0"/>
    </default>
    <default class="buddy_steering">
      <joint type="hinge" axis="0 0 1" limited="false" frictionloss="0.00" damping="0.5" armature="0.005"/>
    </default>
    <default class="buddy_throttle">
      <joint type="hinge" axis="0 1 0" frictionloss="0.001" damping="0.01" armature="0.01" limited="false"/>
    </default>
  </default>

  <worldbody>
    <geom size="4 4 0.01" type="plane" material="grid_floor"/>
    <geom name="wall_north"
        type="box"
        pos="0  4  0.25"
        size="4  0.05  0.25"
        material="gray"/>
    <!-- south wall (bottom edge at y=–2) -->
    <geom name="wall_south"
        type="box"
        pos="0 -4  0.25"
        size="4  0.05  0.25"
        material="gray"/>
    <!-- east wall (right edge at x=+2) -->
    <geom name="wall_east"
        type="box"
        pos="4  0  0.25"
        size="0.05  4  0.25"
        material="gray"/>
    <!-- west wall (left edge at x=–2) -->
    <geom name="wall_west"
        type="box"
        pos="-4  0  0.25"
        size="0.05  4  0.25"
        material="gray"/>

    <!-- pillars -->
    <body name="pillar1" pos=" -2 -2 0.5">
      <geom type="cylinder" size="0.5 0.5"
            material="gray"
            contype="0" conaffinity="0"/>
    </body>
    <body name="pillar2" pos="1 2 0.5">
      <geom type="cylinder" size="0.5 0.5"
            material="gray"
            contype="0" conaffinity="0"/>
    </body>

    <!-- car -->
    <body name="buddy" pos="1.3 0.0 0.0" euler="0 0 90">
      <freejoint/>
      <camera name="buddy_third_person" mode="fixed" pos="-1 0 1" xyaxes="0 -1 0 0.707 0 0.707"/>
      <camera name="overhead_track" mode="track" pos="0 0 9" euler="0 0 0"/>

      <geom pos="0 0 0.094655" contype="0" conaffinity="0" type="mesh" mass="3.542137" mesh="buddy_mushr_base_nano"/>

      <site name="buddy_imu" pos="-0.005 0 .165"/>

      <geom name="buddy_pusher_connector" contype="0" conaffinity="0" pos="0.2073 0 0.063" type="box" size="0.0025 0.025 0.02" mass="0.01" />
      <!-- x=1cm, y=22cm, z=7cm -->
      <geom name="buddy_pusher" contype="0" conaffinity="0" pos="0.215 0 0.048" type="box" size=".005 .11 .035" mass="0.05"/>

      <body name="buddy_steering_wheel" pos="0.1385 0 0.0488">
        <joint class="buddy_steering" name="buddy_steering_wheel"/>
        <geom class="buddy_wheel" contype="0" conaffinity="0" mass="0.01" rgba="0 0 0 1.0"/>
      </body>

      <body name="buddy_wheel_fl" pos="0.1385 0.115 0.0488">
        <joint class="buddy_steering" name="buddy_wheel_fl_steering"/>
        <joint class="buddy_throttle" name="buddy_wheel_fl_throttle"/>
        <geom class="buddy_wheel"/>
        <geom class="buddy_wheel" type="mesh" contype="0" conaffinity="0" group="1" rgba="1 1 1 1"/>
      </body>
      <body name="buddy_wheel_fr" pos="0.1385 -0.115 0.0488">
        <joint class="buddy_steering" name="buddy_wheel_fr_steering"/>
        <joint class="buddy_throttle" name="buddy_wheel_fr_throttle"/>
        <geom class="buddy_wheel"/>
        <geom class="buddy_wheel" type="mesh" contype="0" conaffinity="0" group="1" rgba="1 1 1 1"/>
      </body>
      <body name="buddy_wheel_bl" pos="-0.158 0.115 0.0488">
        <joint class="buddy_throttle" name="buddy_wheel_bl_throttle"/>
        <geom class="buddy_wheel"/>
        <geom class="buddy_wheel" type="mesh" contype="0" conaffinity="0" group="1" rgba="1 1 1 1"/>
      </body>
      <body name="buddy_wheel_br" pos="-0.158 -0.115 0.0488">
        <joint class="buddy_throttle" name="buddy_wheel_br_throttle"/>
        <geom class="buddy_wheel"/>
        <geom class="buddy_wheel" type="mesh" contype="0" conaffinity="0" group="1" rgba="1 1 1 1"/>
      </body>
    </body>
  </worldbody>

  <actuator>
    <position class="buddy_steering" kp="100.0" name="buddy_steering_pos" joint="buddy_steering_wheel" ctrllimited="true" ctrlrange="-1.2 1.2"/>
    <velocity kv="450" gear="0.04" forcelimited="true" forcerange="-300 300" name="buddy_throttle_velocity" tendon="buddy_throttle" ctrllimited="true" ctrlrange="0.0 1.0"/>
  </actuator>

  <equality>
    <!-- taylor expansion of delta_l = arctan(L/(L/tan(delta) - W/2)) with L,W in reference to kinematic car model -->
    <joint joint1="buddy_wheel_fl_steering" joint2="buddy_steering_wheel" polycoef="0 1 0.375 0.140625 -0.0722656"/>

    <!-- taylor expansion of delta_r = arctan(L/(L/tan(delta) + W/2)) with L,W in reference to kinematic car model -->
    <joint joint1="buddy_wheel_fr_steering" joint2="buddy_steering_wheel" polycoef="0 1 -0.375 0.140625 0.0722656"/>
  </equality>

  <tendon>
    <fixed name="buddy_throttle">
      <joint joint="buddy_wheel_fl_throttle" coef="0.25"/>
      <joint joint="buddy_wheel_fr_throttle" coef="0.25"/>
      <joint joint="buddy_wheel_bl_throttle" coef="0.25"/>
      <joint joint="buddy_wheel_br_throttle" coef="0.25"/>
    </fixed>
  </tendon>

  <sensor>
    <framequat name="framequat" objtype='body' objname="buddy"/>
    <velocimeter name="velocimeter" site="buddy_imu" />
    <jointpos name="buddy_steering_pos" joint="buddy_steering_wheel"/>
    <jointvel name="buddy_steering_vel" joint="buddy_steering_wheel"/>
    <jointvel name="buddy_wheel_fl_vel" joint="buddy_wheel_fl_throttle"/>
    <jointvel name="buddy_wheel_fr_vel" joint="buddy_wheel_fr_throttle"/>
    <jointvel name="buddy_wheel_bl_vel" joint="buddy_wheel_bl_throttle"/>
    <jointvel name="buddy_wheel_br_vel" joint="buddy_wheel_br_throttle"/>
  </sensor>
</mujoco>